#VRML_SIM R2023a utf8

EXTERNPROTO "https://raw.githubusercontent.com/cyberbotics/webots/R2023a/projects/objects/backgrounds/protos/TexturedBackground.proto"
EXTERNPROTO "https://raw.githubusercontent.com/cyberbotics/webots/R2023a/projects/objects/backgrounds/protos/TexturedBackgroundLight.proto"
EXTERNPROTO "https://raw.githubusercontent.com/cyberbotics/webots/R2023a/projects/objects/floors/protos/Floor.proto"

WorldInfo {
}
Viewpoint {
  orientation -0.23112341117956503 0.13363238594522725 0.9637034576213306 2.2797258521182817
  position 1.2357794030954143 -1.137360768911159 1.1890844554461781
  followType "None"
}
TexturedBackground {
}
TexturedBackgroundLight {
}
Floor {
  size 5 5
}
Robot {
  rotation 0 1 0 0
  children [
    Hinge2Joint {
      jointParameters HingeJointParameters {
        axis 0 0 1
        anchor 0 0 0.05
      }
      jointParameters2 JointParameters {
        axis 1 0 0
      }
      device [
        RotationalMotor {
          name "shoulder_xy_motor"
        }
        PositionSensor {
          name "shoulder_xy_sensor"
        }
      ]
      device2 [
        RotationalMotor {
          name "shoulder_yz_motor"
        }
        PositionSensor {
          name "shoulder_yz_sensor"
        }
      ]
      endPoint DEF arm Solid {
        translation 0 0 0.25
        rotation 0 1 0 0
        children [
          DEF Elbow Solid {
            translation 0.1 0 0.2
            rotation 1 0 0 0
            children [
              DEF elbow Solid {
                children [
                  Solid {
                    children [
                      Shape {
                        appearance PBRAppearance {
                          baseColor 0 1 1
                        }
                        geometry Box {
                          size 0.1 0.1 0.1
                        }
                      }
                    ]
                    name "elbow"
                  }
                  HingeJoint {
                    jointParameters HingeJointParameters {
                    }
                    device [
                      PositionSensor {
                        name "elbow_sensor"
                      }
                      RotationalMotor {
                        name "elbow_motor"
                      }
                    ]
                    endPoint Solid {
                      translation 0.1 0.15 0
                      rotation 1 0 0 0
                      children [
                        Shape {
                          geometry Box {
                            size 0.1 0.4 0.1
                          }
                        }
                      ]
                    }
                  }
                  Transform {
                  }
                ]
                name "elbow"
              }
            ]
            name "solid(2)"
          }
          DEF upperArm Solid {
            children [
              DEF upperArm Shape {
                appearance PBRAppearance {
                  baseColor 1 0 1
                }
                geometry Box {
                  size 0.1 0.1 0.5
                }
              }
            ]
          }
        ]
        name "solid(3)"
      }
    }
    Transform {
      translation 0 0 0.025
      children [
        DEF base Shape {
          appearance PBRAppearance {
            baseColor 0.5 0.5 0.5
          }
          geometry Box {
            size 0.4 0.4 0.05
          }
        }
      ]
    }
  ]
  boundingObject USE base
  controller "hinge2_arm"
}
